{
    "0": {
        "type": "ERROR",
        "date": "05.10.2020 21:02:30",
        "traceback": "Traceback (most recent call last):\n  File \"/home/userpc/GitProjects/LavAccount/lavaccount/api/service.py\", line 291, in wrapper\n    return function(request)\n  File \"/home/userpc/GitProjects/LavAccount/lavaccount/home/views.py\", line 47, in index\n    Account.objects.get(user='22222')\n  File \"/home/userpc/.local/lib/python3.8/site-packages/django/db/models/manager.py\", line 82, in manager_method\n    return getattr(self.get_queryset(), name)(*args, **kwargs)\n  File \"/home/userpc/.local/lib/python3.8/site-packages/django/db/models/query.py\", line 415, in get\n    raise self.model.DoesNotExist(\napi.models.Account.DoesNotExist: Account matching query does not exist.\n"
    },
    "1": {
        "type": "ERROR",
        "date": "05.10.2020 21:02:33",
        "traceback": "Traceback (most recent call last):\n  File \"/home/userpc/GitProjects/LavAccount/lavaccount/api/service.py\", line 291, in wrapper\n    return function(request)\n  File \"/home/userpc/GitProjects/LavAccount/lavaccount/home/views.py\", line 47, in index\n    Account.objects.get(user='22222')\n  File \"/home/userpc/.local/lib/python3.8/site-packages/django/db/models/manager.py\", line 82, in manager_method\n    return getattr(self.get_queryset(), name)(*args, **kwargs)\n  File \"/home/userpc/.local/lib/python3.8/site-packages/django/db/models/query.py\", line 415, in get\n    raise self.model.DoesNotExist(\napi.models.Account.DoesNotExist: Account matching query does not exist.\n"
    },
    "2": {
        "type": "ERROR",
        "date": "05.10.2020 21:02:37",
        "traceback": "Traceback (most recent call last):\n  File \"/home/userpc/GitProjects/LavAccount/lavaccount/api/service.py\", line 291, in wrapper\n    return function(request)\n  File \"/home/userpc/GitProjects/LavAccount/lavaccount/home/views.py\", line 47, in index\n    Account.objects.get(user='22222')\n  File \"/home/userpc/.local/lib/python3.8/site-packages/django/db/models/manager.py\", line 82, in manager_method\n    return getattr(self.get_queryset(), name)(*args, **kwargs)\n  File \"/home/userpc/.local/lib/python3.8/site-packages/django/db/models/query.py\", line 415, in get\n    raise self.model.DoesNotExist(\napi.models.Account.DoesNotExist: Account matching query does not exist.\n"
    },
    "3": {
        "type": "ERROR",
        "date": "05.10.2020 21:28:29",
        "traceback": "Traceback (most recent call last):\n  File \"/home/userpc/GitProjects/LavAccount/lavaccount/api/service.py\", line 291, in wrapper\n    return function(request)\n  File \"/home/userpc/GitProjects/LavAccount/lavaccount/home/views.py\", line 47, in index\n    Account.objects.get(user='22222')\n  File \"/home/userpc/.local/lib/python3.8/site-packages/django/db/models/manager.py\", line 82, in manager_method\n    return getattr(self.get_queryset(), name)(*args, **kwargs)\n  File \"/home/userpc/.local/lib/python3.8/site-packages/django/db/models/query.py\", line 415, in get\n    raise self.model.DoesNotExist(\napi.models.Account.DoesNotExist: Account matching query does not exist.\n"
    }
}